//entra en catch por que no existe la funcion
try{
    hello();
} catch{
    console.log("error")
}

try{
    anotherfn();
} catch{
    console.log("error")
}